<?xml version="1.0" ?>
<!-- =================================================================================== -->
<!-- |    This document was autogenerated by xacro from snake.urdf                     | -->
<!-- |    EDITING THIS FILE BY HAND IS NOT RECOMMENDED                                 | -->
<!-- =================================================================================== -->
<!-- This URDF was automatically created by SolidWorks to URDF Exporter! Originally created by Stephen Brawner (brawner@gmail.com) 
     Commit Version: 1.6.0-4-g7f85cfe  Build Version: 1.6.7995.38578
     For more information, please see http://wiki.ros.org/sw_urdf_exporter -->
<robot name="snake">
  <link name="base_link">
    <inertial>
      <origin rpy="0 0 0" xyz="-0.000234387980967782 -0.00697698813928649 0.0800930918880029"/>
      <mass value="0.7"/>
      <inertia ixx="5" ixy="0" ixz="0" iyy="5" iyz="0" izz="5"/>
    </inertial>
    <visual>
      <origin rpy="0 0 0" xyz="0 0 0"/>
      <geometry>
        <mesh filename="package://snake_description/meshes/base_link.STL"/>
      </geometry>
      <material name="">
        <color rgba="0.968627450980392 0.87843137254902 0.6 1"/>
      </material>
    </visual>
    <collision>
      <origin rpy="0 0 0" xyz="0 0 0"/>
      <geometry>
        <mesh filename="package://snake_description/meshes/base_link.STL"/>
      </geometry>
    </collision>
  </link>
  <link name="l1">
    <inertial>
      <origin rpy="0 0 0" xyz="-9.30008088317891E-08 6.32183255932228E-05 2.34841335058911E-08"/>
      <mass value="0.5"/>
      <inertia ixx="5" ixy="0" ixz="0" iyy="5" iyz="0" izz="5"/>
    </inertial>
    <visual>
      <origin rpy="0 0 0" xyz="0 0 0"/>
      <geometry>
        <mesh filename="package://snake_description/meshes/l1.STL"/>
      </geometry>
      <material name="">
        <color rgba="1 1 1 1"/>
      </material>
    </visual>
    <collision>
      <origin rpy="0 0 0" xyz="0 0 0"/>
      <geometry>
        <mesh filename="package://snake_description/meshes/l1.STL"/>
      </geometry>
    </collision>
  </link>
  <joint name="j1" type="revolute">
    <origin rpy="0 0 0" xyz="-0.00023776 -0.09187 0.078152"/>
    <parent link="base_link"/>
    <child link="l1"/>
    <axis xyz="1 0 0"/>
    <limit effort="100" lower="-7" upper="7" velocity="100"/>
  </joint>
  <link name="l2">
    <inertial>
      <origin rpy="0 0 0" xyz="0.00300986957255078 -0.0868389503008905 0.00190271917035976"/>
      <mass value="0.7"/>
      <inertia ixx="5" ixy="0" ixz="0" iyy="5" iyz="0" izz="5"/>
    </inertial>
    <visual>
      <origin rpy="0 0 0" xyz="0 0 0"/>
      <geometry>
        <mesh filename="package://snake_description/meshes/l2.STL"/>
      </geometry>
      <material name="">
        <color rgba="0.6 0.6 0.6 1"/>
      </material>
    </visual>
    <collision>
      <origin rpy="0 0 0" xyz="0 0 0"/>
      <geometry>
        <mesh filename="package://snake_description/meshes/l2.STL"/>
      </geometry>
    </collision>
  </link>
  <joint name="j2" type="revolute">
    <origin rpy="0 0 0" xyz="0 -0.025 0"/>
    <parent link="l1"/>
    <child link="l2"/>
    <axis xyz="0 0 -1"/>
    <limit effort="100" lower="-7" upper="7" velocity="100"/>
  </joint>
  <link name="l3">
    <inertial>
      <origin rpy="0 0 0" xyz="-2.27777575889654E-06 6.31778937628669E-05 2.33684780207022E-08"/>
      <mass value="0.5"/>
       <inertia ixx="5" ixy="0" ixz="0" iyy="5" iyz="0" izz="5"/>
    </inertial>
    <visual>
      <origin rpy="0 0 0" xyz="0 0 0"/>
      <geometry>
        <mesh filename="package://snake_description/meshes/l3.STL"/>
      </geometry>
      <material name="">
        <color rgba="1 1 1 1"/>
      </material>
    </visual>
    <collision>
      <origin rpy="0 0 0" xyz="0 0 0"/>
      <geometry>
        <mesh filename="package://snake_description/meshes/l3.STL"/>
      </geometry>
    </collision>
  </link>
  <joint name="j3" type="revolute">
    <origin rpy="0 0 0" xyz="0.00615167738184841 -0.177893667299857 0"/>
    <parent link="l2"/>
    <child link="l3"/>
    <axis xyz="0.999402625280054 0.0345599852913034 0"/>
    <limit effort="100" lower="-7" upper="7" velocity="100"/>
  </joint>
  <link name="l4">
    <inertial>
      <origin rpy="0 0 0" xyz="0.00600921102535792 -0.0866830524957057 0.00190271617698692"/>
      <mass value="0.707086339902103"/>
       <inertia ixx="5" ixy="0" ixz="0" iyy="5" iyz="0" izz="5"/>
    </inertial>
    <visual>
      <origin rpy="0 0 0" xyz="0 0 0"/>
      <geometry>
        <mesh filename="package://snake_description/meshes/l4.STL"/>
      </geometry>
      <material name="">
        <color rgba="0.6 0.6 0.6 1"/>
      </material>
    </visual>
    <collision>
      <origin rpy="0 0 0" xyz="0 0 0"/>
      <geometry>
        <mesh filename="package://snake_description/meshes/l4.STL"/>
      </geometry>
    </collision>
  </link>
  <joint name="j4" type="revolute">
    <origin rpy="0 0 0" xyz="0.000863999632282564 -0.0249850656320013 0"/>
    <parent link="l3"/>
    <child link="l4"/>
    <axis xyz="0 0 -1"/>
    <limit effort="100" lower="-7" upper="7" velocity="100"/>
  </joint>
  <link name="l5">
    <inertial>
      <origin rpy="0 0 0" xyz="-4.4598296490006E-06 6.30614553610576E-05 2.33497702943619E-08"/>
      <mass value="0.5"/>
       <inertia ixx="5" ixy="0" ixz="0" iyy="5" iyz="0" izz="5"/>
    </inertial>
    <visual>
      <origin rpy="0 0 0" xyz="0 0 0"/>
      <geometry>
        <mesh filename="package://snake_description/meshes/l5.STL"/>
      </geometry>
      <material name="">
        <color rgba="1 1 1 1"/>
      </material>
    </visual>
    <collision>
      <origin rpy="0 0 0" xyz="0 0 0"/>
      <geometry>
        <mesh filename="package://snake_description/meshes/l5.STL"/>
      </geometry>
    </collision>
  </link>
  <joint name="j5" type="revolute">
    <origin rpy="0 0 0" xyz="0.0122960050505949 -0.177574796240332 0"/>
    <parent link="l4"/>
    <child link="l5"/>
    <axis xyz="0.99761121483333 0.0690786800595353 0"/>
    <limit effort="100" lower="-7" upper="7" velocity="100"/>
  </joint>
  <link name="l6">
    <inertial>
      <origin rpy="0 0 0" xyz="0.00900137343373282 -0.0864234981702365 0.00190269434190572"/>
      <mass value="0.707087058502178"/>
       <inertia ixx="5" ixy="0" ixz="0" iyy="5" iyz="0" izz="5"/>
    </inertial>
    <visual>
      <origin rpy="0 0 0" xyz="0 0 0"/>
      <geometry>
        <mesh filename="package://snake_description/meshes/l6.STL"/>
      </geometry>
      <material name="">
        <color rgba="0.6 0.6 0.6 1"/>
      </material>
    </visual>
    <collision>
      <origin rpy="0 0 0" xyz="0 0 0"/>
      <geometry>
        <mesh filename="package://snake_description/meshes/l6.STL"/>
      </geometry>
    </collision>
  </link>
  <joint name="j6" type="revolute">
    <origin rpy="0 0 0" xyz="0.00172696700148839 -0.0249402803708333 0"/>
    <parent link="l5"/>
    <child link="l6"/>
    <axis xyz="0 0 -1"/>
    <limit effort="100" lower="-7" upper="7" velocity="100"/>
  </joint>
  <link name="l7">
    <inertial>
      <origin rpy="0 0 0" xyz="-6.63653621674198E-06 6.28690839595825E-05 2.34841427936006E-08"/>
      <mass value="0.5"/>
       <inertia ixx="5" ixy="0" ixz="0" iyy="5" iyz="0" izz="5"/>
    </inertial>
    <visual>
      <origin rpy="0 0 0" xyz="0 0 0"/>
      <geometry>
        <mesh filename="package://snake_description/meshes/l7.STL"/>
      </geometry>
      <material name="">
        <color rgba="1 1 1 1"/>
      </material>
    </visual>
    <collision>
      <origin rpy="0 0 0" xyz="0 0 0"/>
      <geometry>
        <mesh filename="package://snake_description/meshes/l7.STL"/>
      </geometry>
    </collision>
  </link>
  <joint name="j7" type="revolute">
    <origin rpy="0 0 0" xyz="0.0184256420741932 -0.177043767792469 0"/>
    <parent link="l6"/>
    <child link="l7"/>
    <axis xyz="0.994627908946454 0.103514843113459 0"/>
    <limit effort="100" lower="-7" upper="7" velocity="100"/>
  </joint>
  <link name="l8">
    <inertial>
      <origin rpy="0 0 0" xyz="0.0115173506251668 -0.0827314123962982 0.00191470380704411"/>
      <mass value="0.702654051556184"/>
       <inertia ixx="5" ixy="0" ixz="0" iyy="5" iyz="0" izz="5"/>
    </inertial>
    <visual>
      <origin rpy="0 0 0" xyz="0 0 0"/>
      <geometry>
        <mesh filename="package://snake_description/meshes/l8.STL"/>
      </geometry>
      <material name="">
        <color rgba="0.6 0.6 0.6 1"/>
      </material>
    </visual>
    <collision>
      <origin rpy="0 0 0" xyz="0 0 0"/>
      <geometry>
        <mesh filename="package://snake_description/meshes/l8.STL"/>
      </geometry>
    </collision>
  </link>
  <joint name="j8" type="revolute">
    <origin rpy="0 0 0" xyz="0.00258787107783648 -0.0248656977236614 0"/>
    <parent link="l7"/>
    <child link="l8"/>
    <axis xyz="0 0 -1"/>
    <limit effort="100" lower="-7" upper="7" velocity="100"/>
  </joint>
  
  <link name="w5.1">
        <inertial>
            <origin xyz="-1.11022302462516E-16 -3.02258218454199E-14 4.5102810375397E-17" rpy="0 0 0" />
            <mass value="0.0110969343557345" />
            <inertia ixx="1.11072386362244E-06" ixy="-2.85211875208284E-21" ixz="-6.61744490042422E-24" iyy="2.05541073669667E-06" iyz="1.05879118406788E-22" izz="1.11072386362244E-06" />
        </inertial>
        <visual>
            <origin xyz="0 0 0" rpy="0 0 0" />
            <geometry>
                <mesh filename="package://snake_description/meshes/w5.1.STL" />
            </geometry>
            <material name="">
                <color rgba="0.6 0.6 0.6 1" />
            </material>
        </visual>
        <collision>
            <origin xyz="0 0 0" rpy="0 0 0" />
            <geometry>
                <mesh filename="package://snake_description/meshes/w5.1.STL" />
                
            </geometry>
        </collision>
    </link>
    <joint name="j5.1" type="revolute">
        <origin xyz="0.046933 -0.083327 -0.060622" rpy="-0.52464 0.059931 1.6744" />
        <parent link="l8" />
        <child link="w5.1" />
        <axis xyz="0 1 0" />
        <limit lower="-7" upper="7" effort="100" velocity="100" />
    </joint>
    <link name="w5.2">
        <inertial>
            <origin xyz="1.11022302462516E-16 -3.56381590904675E-14 1.38777878078145E-17" rpy="0 0 0" />
            <mass value="0.0110969343557345" />
            <inertia ixx="1.11072386362244E-06" ixy="1.00916034731469E-21" ixz="1.98523347012727E-23" iyy="2.05541073669667E-06" iyz="-2.11758236813575E-22" izz="1.11072386362244E-06" />
        </inertial>
        <visual>
            <origin xyz="0 0 0" rpy="0 0 0" />
            <geometry>
                <mesh filename="package://snake_description/meshes/w5.2.STL" />
            </geometry>
            <material name="">
                <color rgba="0.6 0.6 0.6 1" />
            </material>
        </visual>
        <collision>
            <origin xyz="0 0 0" rpy="0 0 0" />
            <geometry>
                <mesh filename="package://snake_description/meshes/w5.2.STL" />
                
            </geometry>
        </collision>
    </link>
    <joint name="j5.2" type="revolute">
        <origin xyz="-0.022399 -0.092975 -0.060622" rpy="0.52464 -0.059931 1.6744" />
        <parent link="l8" />
        <child link="w5.2" />
        <axis xyz="0 1 0" />
        <limit lower="-7" upper="7" effort="100" velocity="100" />
    </joint>
    <link name="w4.1">
        <inertial>
            <origin xyz="2.22044604925031E-16 0.005 1.38777878078145E-17" rpy="0 0 0" />
            <mass value="0.0110969343557345" />
            <inertia ixx="1.11072386362244E-06" ixy="2.53282703563737E-21" ixz="-1.07533479631894E-23" iyy="2.05541073669667E-06" iyz="2.64697796016969E-22" izz="1.11072386362244E-06" />
        </inertial>
        <visual>
            <origin xyz="0 0 0" rpy="0 0 0" />
            <geometry>
                <mesh filename="package://snake_description/meshes/w4.1.STL" />
               
            </geometry>
            <material name="">
                <color rgba="0.6 0.6 0.6 1" />
            </material>
        </visual>
        <collision>
            <origin xyz="0 0 0" rpy="0 0 0" />
            <geometry>
                <mesh filename="package://snake_description/meshes/w4.1.STL" />
            </geometry>
        </collision>
    </link>
    <joint name="j4.1" type="revolute">
        <origin xyz="0.039718 -0.085347 -0.063122" rpy="0.52363 -0.10658 -1.4732" />
        <parent link="l6" />
        <child link="w4.1" />
        <axis xyz="0 0 0" />
        <limit lower="-7" upper="7" effort="100" velocity="100" />
    </joint>
    <link name="w4.2">
        <inertial>
            <origin xyz="-2.22044604925031E-16 0.00499999999999998 1.73472347597681E-17" rpy="0 0 0" />
            <mass value="0.0110969343557345" />
            <inertia ixx="1.11072386362244E-06" ixy="-1.35657620458697E-21" ixz="-1.32348898008484E-23" iyy="2.05541073669667E-06" iyz="-7.94093388050907E-23" izz="1.11072386362244E-06" />
        </inertial>
        <visual>
            <origin xyz="0 0 0" rpy="0 0 0" />
            <geometry>
                <mesh filename="package://snake_description/meshes/w4.2.STL" />
                
            </geometry>
            <material name="">
                <color rgba="0.6 0.6 0.6 1" />
            </material>
        </visual>
        <collision>
            <origin xyz="0 0 0" rpy="0 0 0" />
            <geometry>
                <mesh filename="package://s2/meshes/w4.2.STL" />
            </geometry>
        </collision>
    </link>
    <joint name="j4.2" type="revolute">
        <origin xyz="-0.029906 -0.092593 -0.058122" rpy="-0.52991 0.14706 -1.5527" />
        <parent link="l6" />
        <child link="w4.2" />
        <axis xyz="0 1 0" />
        <limit lower="-7" upper="7" effort="100" velocity="100" />
    </joint>
    <link name="w3.1">
        <inertial>
            <origin xyz="-1.11022302462516E-16 0.005 1.38777878078145E-17" rpy="0 0 0" />
            <mass value="0.0110969343557345" />
            <inertia ixx="1.11072386362244E-06" ixy="1.90871926346611E-21" ixz="-2.48154183765908E-24" iyy="2.05541073669667E-06" iyz="3.70576914423756E-22" izz="1.11072386362244E-06" />
        </inertial>
        <visual>
            <origin xyz="0 0 0" rpy="0 0 0" />
            <geometry>
                <mesh filename="package://snake_description/meshes/w3.1.STL" />
              
            </geometry>
            <material name="">
                <color rgba="0.6 0.6 0.6 1" />
            </material>
        </visual>
        <collision>
            <origin xyz="0 0 0" rpy="0 0 0" />
            <geometry>
                <mesh filename="package://snake_description/meshes/w3.1.STL" />
                
            </geometry>
        </collision>
    </link>
    <joint name="j3.1" type="revolute">
        <origin xyz="0.036745 -0.086669 -0.063122" rpy="0.52363 -0.010658 -1.5078" />
        <parent link="l4" />
        <child link="w3.1" />
        <axis xyz="0 1 0" />
        <limit lower="-7" upper="7" effort="100" velocity="100" />
    </joint>
    <link name="w3.2">
        <inertial>
            <origin xyz="-1.11022302462516E-16 0.00500000000000003 0" rpy="0 0 0" />
            <mass value="0.0110969343557345" />
            <inertia ixx="1.11072386362244E-06" ixy="-2.24331382124381E-21" ixz="5.29395592033938E-23" iyy="2.05541073669667E-06" iyz="-1.32348898008484E-21" izz="1.11072386362244E-06" />
        </inertial>
        <visual>
            <origin xyz="0 0 0" rpy="0 0 0" />
            <geometry>
                <mesh filename="package://snake_description/meshes/w3.2.STL" />
            </geometry>
            <material name="">
                <color rgba="0.6 0.6 0.6 1" />
            </material>
        </visual>
        <collision>
            <origin xyz="0 0 0" rpy="0 0 0" />
            <geometry>
                <mesh filename="package://snake_description/meshes/w3.2.STL" />
                
            </geometry>
        </collision>
    </link>
    <joint name="j3.2" type="revolute">
        <origin xyz="-0.033088 -0.091504 -0.058122" rpy="-0.52991 0.14706 -1.5873" />
        <parent link="l4" />
        <child link="w3.2" />
        <axis xyz="0 1 0" />
        <limit lower="-7" upper="7" effort="100" velocity="100" />
    </joint>
    <link name="w2.1">
        <inertial>
            <origin xyz="-5.55111512312578E-17 0.00500000000000002 6.93889390390723E-18" rpy="0 0 0" />
            <mass value="0.0110969343557345" />
            <inertia ixx="1.11072386362244E-06" ixy="1.92733082724855E-21" ixz="-1.65436122510606E-24" iyy="2.05541073669667E-06" iyz="0" izz="1.11072386362244E-06" />
        </inertial>
        <visual>
            <origin xyz="0 0 0" rpy="0 0 0" />
            <geometry>
                <mesh filename="package://snake_description/meshes/w2.1.STL" />
            </geometry>
            <material name="">
                <color rgba="0.6 0.6 0.6 1" />
            </material>
        </visual>
        <collision>
            <origin xyz="0 0 0" rpy="0 0 0" />
            <geometry>
                <mesh filename="package://snake_description/meshes/w2.1.STL" />
              
            </geometry>
        </collision>
    </link>
    <joint name="j2.1" type="revolute">
        <origin xyz="0.033727 -0.087887 -0.063122" rpy="0.52363 -0.010658 -1.5424" />
        <parent link="l2" />
        <child link="w2.1" />
        <axis xyz="0 0 0" />
        <limit lower="-7" upper="7" effort="100" velocity="100" />
    </joint>
    <link name="w2.2">
        <inertial>
            <origin xyz="-5.55111512312578E-17 0.005 0" rpy="0 0 0" />
            <mass value="0.0110969343557345" />
            <inertia ixx="1.11072386362244E-06" ixy="2.58080351116545E-21" ixz="-1.32348898008484E-23" iyy="2.05541073669667E-06" iyz="-1.85288457211878E-22" izz="1.11072386362244E-06" />
        </inertial>
        <visual>
            <origin xyz="0 0 0" rpy="0 0 0" />
            <geometry>
                <mesh filename="package://snake_description/meshes/w2.2.STL" />
                
            </geometry>
            <material name="">
                <color rgba="0.6 0.6 0.6 1" />
            </material>
        </visual>
        <collision>
            <origin xyz="0 0 0" rpy="0 0 0" />
            <geometry>
                <mesh filename="package://snake_description/meshes/w2.2.STL" />
            </geometry>
        </collision>
    </link>
    <joint name="j2.2" type="revolute">
        <origin xyz="-0.036231 -0.090306 -0.058122" rpy="-0.52991 0.14706 -1.6219" />
        <parent link="l2" />
        <child link="w2.2" />
        <axis xyz="0 0 0" />
        <limit lower="-7" upper="7" effort="100" velocity="100" />
    </joint>
    <link name="w1.1">
        <inertial>
            <origin xyz="-2.77555756156289E-17 0.005 0" rpy="0 0 0" />
            <mass value="0.0110969343557345" />
            <inertia ixx="1.11072386362244E-06" ixy="-1.0319078141599E-21" ixz="-8.27180612553028E-25" iyy="2.05541073669667E-06" iyz="3.17637355220363E-22" izz="1.11072386362244E-06" />
        </inertial>
        <visual>
            <origin xyz="0 0 0" rpy="0 0 0" />
            <geometry>
                <mesh filename="package://snake_description/meshes/w1.1.STL" />
            </geometry>
            <material name="">
                <color rgba="0.6 0.6 0.6 1" />
            </material>
        </visual>
        <collision>
            <origin xyz="0 0 0" rpy="0 0 0" />
            <geometry>
                <mesh filename="package://snake_description/meshes/w1.1.STL" />
               
            </geometry>
        </collision>
    </link>
    <joint name="j1.1" type="revolute">
        <origin xyz="0.030432 -0.0028698 0.01503" rpy="0.52363 -0.010658 -1.5769" />
        <parent link="base_link" />
        <child link="w1.1" />
        <axis xyz="0 1 0" />
        <limit lower="-7" upper="7" effort="100" velocity="100" />
    </joint>
    <link name="w1.2">
        <inertial>
            <origin xyz="2.77555756156289E-17 0.005 0" rpy="0 0 0" />
            <mass value="0.0110969343557345" />
            <inertia ixx="1.11072386362244E-06" ixy="6.28657265540301E-22" ixz="6.61744490042422E-23" iyy="2.05541073669667E-06" iyz="-2.64697796016969E-23" izz="1.11072386362244E-06" />
        </inertial>
        <visual>
            <origin xyz="0 0 0" rpy="0 0 0" />
            <geometry>
                <mesh filename="package://snake_description/meshes/w1.2.STL" />
            </geometry>
            <material name="">
                <color rgba="0.6 0.6 0.6 1" />
            </material>
        </visual>
        <collision>
            <origin xyz="0 0 0" rpy="0 0 0" />
            <geometry>
                <mesh filename="package://snake_description/meshes/w1.2.STL" />
                
            </geometry>
        </collision>
    </link>
    <joint name="j1.2" type="revolute">
        <origin xyz="-0.039568 -0.0028698 0.02003" rpy="-0.52991 0.14706 -1.6564" />
        <parent link="base_link" />
        <child link="w1.2" />
        <axis xyz="0 0 0" />
        <limit lower="-7" upper="7" effort="100" velocity="100" />
    </joint>
    
  <transmission name="trans_j1">
    <type>transmission_interface/SimpleTransmission</type>
    <joint name="j1">
      <hardwareInterface>hardware_interface/EffortJointInterface</hardwareInterface>
    </joint>
    <actuator name="j1_motor">
      <hardwareInterface>hardware_interface/EffortJointInterface</hardwareInterface>
      <mechanicalReduction>1</mechanicalReduction>
    </actuator>
  </transmission>
  
  <transmission name="trans_j2">
    <type>transmission_interface/SimpleTransmission</type>
    <joint name="j2">
      <hardwareInterface>hardware_interface/EffortJointInterface</hardwareInterface>
    </joint>
    <actuator name="j2_motor">
      <hardwareInterface>hardware_interface/EffortJointInterface</hardwareInterface>
      <mechanicalReduction>1</mechanicalReduction>
    </actuator>
  </transmission>
  
  <transmission name="trans_j3">
    <type>transmission_interface/SimpleTransmission</type>
    <joint name="j3">
      <hardwareInterface>hardware_interface/EffortJointInterface</hardwareInterface>
    </joint>
    <actuator name="j3_motor">
      <hardwareInterface>hardware_interface/EffortJointInterface</hardwareInterface>
      <mechanicalReduction>1</mechanicalReduction>
    </actuator>
  </transmission>
  
  <transmission name="trans_j4">
    <type>transmission_interface/SimpleTransmission</type>
    <joint name="j4">
      <hardwareInterface>hardware_interface/EffortJointInterface</hardwareInterface>
    </joint>
    <actuator name="j4_motor">
      <hardwareInterface>hardware_interface/EffortJointInterface</hardwareInterface>
      <mechanicalReduction>1</mechanicalReduction>
    </actuator>
  </transmission>
  
  <transmission name="trans_j5">
    <type>transmission_interface/SimpleTransmission</type>
    <joint name="j5">
      <hardwareInterface>hardware_interface/EffortJointInterface</hardwareInterface>
    </joint>
    <actuator name="j5_motor">
      <hardwareInterface>hardware_interface/EffortJointInterface</hardwareInterface>
      <mechanicalReduction>1</mechanicalReduction>
    </actuator>
  </transmission>
  
  <transmission name="trans_j6">
    <type>transmission_interface/SimpleTransmission</type>
    <joint name="j6">
      <hardwareInterface>hardware_interface/EffortJointInterface</hardwareInterface>
    </joint>
    <actuator name="j6_motor">
      <hardwareInterface>hardware_interface/EffortJointInterface</hardwareInterface>
      <mechanicalReduction>1</mechanicalReduction>
    </actuator>
  </transmission>
  
  <transmission name="trans_j7">
    <type>transmission_interface/SimpleTransmission</type>
    <joint name="j7">
      <hardwareInterface>hardware_interface/EffortJointInterface</hardwareInterface>
    </joint>
    <actuator name="j7_motor">
      <hardwareInterface>hardware_interface/EffortJointInterface</hardwareInterface>
      <mechanicalReduction>1</mechanicalReduction>
    </actuator>
  </transmission>
  
  <transmission name="trans_j8">
    <type>transmission_interface/SimpleTransmission</type>
    <joint name="j8">
      <hardwareInterface>hardware_interface/EffortJointInterface</hardwareInterface>
    </joint>
    <actuator name="j8_motor">
      <hardwareInterface>hardware_interface/EffortJointInterface</hardwareInterface>
      <mechanicalReduction>1</mechanicalReduction>
    </actuator>
  </transmission>
  
 
 <transmission name="trans_j5.1">
        <type>transmission_interface/SimpleTransmission</type>
        <joint name="j5.1">
            <hardwareInterface>hardware_interface/EffortJointInterface</hardwareInterface>
        </joint>
        <actuator name="j5.1_motor">
            <hardwareInterface>hardware_interface/EffortJointInterface</hardwareInterface>
            <mechanicalReduction>1</mechanicalReduction>
        </actuator>
    </transmission>
    <transmission name="trans_j5.2">
        <type>transmission_interface/SimpleTransmission</type>
        <joint name="j5.2">
            <hardwareInterface>hardware_interface/EffortJointInterface</hardwareInterface>
        </joint>
        <actuator name="j5.2_motor">
            <hardwareInterface>hardware_interface/EffortJointInterface</hardwareInterface>
            <mechanicalReduction>1</mechanicalReduction>
        </actuator>
    </transmission>
    <transmission name="trans_j4.1">
        <type>transmission_interface/SimpleTransmission</type>
        <joint name="j4.1">
            <hardwareInterface>hardware_interface/EffortJointInterface</hardwareInterface>
        </joint>
        <actuator name="j4.1_motor">
            <hardwareInterface>hardware_interface/EffortJointInterface</hardwareInterface>
            <mechanicalReduction>1</mechanicalReduction>
        </actuator>
    </transmission>
    <transmission name="trans_j4.2">
        <type>transmission_interface/SimpleTransmission</type>
        <joint name="j4.2">
            <hardwareInterface>hardware_interface/EffortJointInterface</hardwareInterface>
        </joint>
        <actuator name="j4.2_motor">
            <hardwareInterface>hardware_interface/EffortJointInterface</hardwareInterface>
            <mechanicalReduction>1</mechanicalReduction>
        </actuator>
    </transmission>
    <transmission name="trans_j3.1">
        <type>transmission_interface/SimpleTransmission</type>
        <joint name="j3.1">
            <hardwareInterface>hardware_interface/EffortJointInterface</hardwareInterface>
        </joint>
        <actuator name="j3.1_motor">
            <hardwareInterface>hardware_interface/EffortJointInterface</hardwareInterface>
            <mechanicalReduction>1</mechanicalReduction>
        </actuator>
    </transmission>
    <transmission name="trans_j3.2">
        <type>transmission_interface/SimpleTransmission</type>
        <joint name="j3.2">
            <hardwareInterface>hardware_interface/EffortJointInterface</hardwareInterface>
        </joint>
        <actuator name="j3.2_motor">
            <hardwareInterface>hardware_interface/EffortJointInterface</hardwareInterface>
            <mechanicalReduction>1</mechanicalReduction>
        </actuator>
    </transmission>
    <transmission name="trans_j2.1">
        <type>transmission_interface/SimpleTransmission</type>
        <joint name="j2.1">
            <hardwareInterface>hardware_interface/EffortJointInterface</hardwareInterface>
        </joint>
        <actuator name="j2.1_motor">
            <hardwareInterface>hardware_interface/EffortJointInterface</hardwareInterface>
            <mechanicalReduction>1</mechanicalReduction>
        </actuator>
    </transmission>
    <transmission name="trans_j2.2">
        <type>transmission_interface/SimpleTransmission</type>
        <joint name="j2.2">
            <hardwareInterface>hardware_interface/EffortJointInterface</hardwareInterface>
        </joint>
        <actuator name="j2.2_motor">
            <hardwareInterface>hardware_interface/EffortJointInterface</hardwareInterface>
            <mechanicalReduction>1</mechanicalReduction>
        </actuator>
    </transmission>
    <transmission name="trans_j1.1">
        <type>transmission_interface/SimpleTransmission</type>
        <joint name="j1.1">
            <hardwareInterface>hardware_interface/EffortJointInterface</hardwareInterface>
        </joint>
        <actuator name="j1.1_motor">
            <hardwareInterface>hardware_interface/EffortJointInterface</hardwareInterface>
            <mechanicalReduction>1</mechanicalReduction>
        </actuator>
    </transmission>
    <transmission name="trans_j1.2">
        <type>transmission_interface/SimpleTransmission</type>
        <joint name="j1.2">
            <hardwareInterface>hardware_interface/EffortJointInterface</hardwareInterface>
        </joint>
        <actuator name="j1.2_motor">
            <hardwareInterface>hardware_interface/EffortJointInterface</hardwareInterface>
            <mechanicalReduction>1</mechanicalReduction>
        </actuator>
    </transmission>
   
  <gazebo>
    <plugin filename="libgazebo_ros_control.so" name="gazebo_ros_control">
      <robotNamespace>/snake</robotNamespace>
    </plugin>
  </gazebo>
</robot>
